<?xml version="1.0" encoding="UTF-8"?>
<testng-results skipped="0" failed="2" total="5" passed="3">
  <reporter-output>
  </reporter-output>
  <suite name="Default suite" duration-ms="34129" started-at="2019-11-21T07:09:14Z" finished-at="2019-11-21T07:09:48Z">
    <groups>
    </groups>
    <test name="Default test" duration-ms="34129" started-at="2019-11-21T07:09:14Z" finished-at="2019-11-21T07:09:48Z">
      <class name="autotest.Lession06">
        <test-method status="PASS" signature="beforeClass()[pri:0, instance:autotest.Lession06@7e0babb1]" name="beforeClass" is-config="true" duration-ms="6902" started-at="2019-11-21T14:09:14Z" finished-at="2019-11-21T14:09:21Z">
          <reporter-output>
          </reporter-output>
        </test-method> <!-- beforeClass -->
        <test-method status="PASS" signature="TC_01()[pri:0, instance:autotest.Lession06@7e0babb1]" name="TC_01" duration-ms="2521" started-at="2019-11-21T14:09:21Z" finished-at="2019-11-21T14:09:23Z">
          <reporter-output>
          </reporter-output>
        </test-method> <!-- TC_01 -->
        <test-method status="FAIL" signature="TC_02()[pri:0, instance:autotest.Lession06@7e0babb1]" name="TC_02" duration-ms="14388" started-at="2019-11-21T14:09:23Z" finished-at="2019-11-21T14:09:37Z">
          <exception class="java.lang.AssertionError">
            <message>
              <![CDATA[expected [true] but found [false]]]>
            </message>
            <full-stacktrace>
              <![CDATA[java.lang.AssertionError: expected [true] but found [false]
	at org.testng.Assert.fail(Assert.java:94)
	at org.testng.Assert.failNotEquals(Assert.java:496)
	at org.testng.Assert.assertTrue(Assert.java:42)
	at org.testng.Assert.assertTrue(Assert.java:52)
	at autotest.Lession06.TC_02(Lession06.java:51)
	at sun.reflect.NativeMethodAccessorImpl.invoke0(Native Method)
	at sun.reflect.NativeMethodAccessorImpl.invoke(Unknown Source)
	at sun.reflect.DelegatingMethodAccessorImpl.invoke(Unknown Source)
	at java.lang.reflect.Method.invoke(Unknown Source)
	at org.testng.internal.MethodInvocationHelper.invokeMethod(MethodInvocationHelper.java:85)
	at org.testng.internal.Invoker.invokeMethod(Invoker.java:639)
	at org.testng.internal.Invoker.invokeTestMethod(Invoker.java:816)
	at org.testng.internal.Invoker.invokeTestMethods(Invoker.java:1124)
	at org.testng.internal.TestMethodWorker.invokeTestMethods(TestMethodWorker.java:125)
	at org.testng.internal.TestMethodWorker.run(TestMethodWorker.java:108)
	at org.testng.TestRunner.privateRun(TestRunner.java:774)
	at org.testng.TestRunner.run(TestRunner.java:624)
	at org.testng.SuiteRunner.runTest(SuiteRunner.java:359)
	at org.testng.SuiteRunner.runSequentially(SuiteRunner.java:354)
	at org.testng.SuiteRunner.privateRun(SuiteRunner.java:312)
	at org.testng.SuiteRunner.run(SuiteRunner.java:261)
	at org.testng.SuiteRunnerWorker.runSuite(SuiteRunnerWorker.java:52)
	at org.testng.SuiteRunnerWorker.run(SuiteRunnerWorker.java:86)
	at org.testng.TestNG.runSuitesSequentially(TestNG.java:1215)
	at org.testng.TestNG.runSuitesLocally(TestNG.java:1140)
	at org.testng.TestNG.run(TestNG.java:1048)
	at org.testng.remote.RemoteTestNG.run(RemoteTestNG.java:112)
	at org.testng.remote.RemoteTestNG.initAndRun(RemoteTestNG.java:205)
	at org.testng.remote.RemoteTestNG.main(RemoteTestNG.java:176)
]]>
            </full-stacktrace>
          </exception> <!-- java.lang.AssertionError -->
          <reporter-output>
          </reporter-output>
        </test-method> <!-- TC_02 -->
        <test-method status="PASS" signature="TC_03()[pri:0, instance:autotest.Lession06@7e0babb1]" name="TC_03" duration-ms="8902" started-at="2019-11-21T14:09:37Z" finished-at="2019-11-21T14:09:46Z">
          <reporter-output>
          </reporter-output>
        </test-method> <!-- TC_03 -->
        <test-method status="FAIL" signature="TC_04()[pri:0, instance:autotest.Lession06@7e0babb1]" name="TC_04" duration-ms="1041" started-at="2019-11-21T14:09:46Z" finished-at="2019-11-21T14:09:47Z">
          <exception class="java.lang.AssertionError">
            <message>
              <![CDATA[expected [You clicked an alert successfully ] but found [You clicked an alert successfully]]]>
            </message>
            <full-stacktrace>
              <![CDATA[java.lang.AssertionError: expected [You clicked an alert successfully ] but found [You clicked an alert successfully]
	at org.testng.Assert.fail(Assert.java:94)
	at org.testng.Assert.failNotEquals(Assert.java:496)
	at org.testng.Assert.assertEquals(Assert.java:125)
	at org.testng.Assert.assertEquals(Assert.java:178)
	at org.testng.Assert.assertEquals(Assert.java:188)
	at autotest.Lession06.TC_04(Lession06.java:76)
	at sun.reflect.NativeMethodAccessorImpl.invoke0(Native Method)
	at sun.reflect.NativeMethodAccessorImpl.invoke(Unknown Source)
	at sun.reflect.DelegatingMethodAccessorImpl.invoke(Unknown Source)
	at java.lang.reflect.Method.invoke(Unknown Source)
	at org.testng.internal.MethodInvocationHelper.invokeMethod(MethodInvocationHelper.java:85)
	at org.testng.internal.Invoker.invokeMethod(Invoker.java:639)
	at org.testng.internal.Invoker.invokeTestMethod(Invoker.java:816)
	at org.testng.internal.Invoker.invokeTestMethods(Invoker.java:1124)
	at org.testng.internal.TestMethodWorker.invokeTestMethods(TestMethodWorker.java:125)
	at org.testng.internal.TestMethodWorker.run(TestMethodWorker.java:108)
	at org.testng.TestRunner.privateRun(TestRunner.java:774)
	at org.testng.TestRunner.run(TestRunner.java:624)
	at org.testng.SuiteRunner.runTest(SuiteRunner.java:359)
	at org.testng.SuiteRunner.runSequentially(SuiteRunner.java:354)
	at org.testng.SuiteRunner.privateRun(SuiteRunner.java:312)
	at org.testng.SuiteRunner.run(SuiteRunner.java:261)
	at org.testng.SuiteRunnerWorker.runSuite(SuiteRunnerWorker.java:52)
	at org.testng.SuiteRunnerWorker.run(SuiteRunnerWorker.java:86)
	at org.testng.TestNG.runSuitesSequentially(TestNG.java:1215)
	at org.testng.TestNG.runSuitesLocally(TestNG.java:1140)
	at org.testng.TestNG.run(TestNG.java:1048)
	at org.testng.remote.RemoteTestNG.run(RemoteTestNG.java:112)
	at org.testng.remote.RemoteTestNG.initAndRun(RemoteTestNG.java:205)
	at org.testng.remote.RemoteTestNG.main(RemoteTestNG.java:176)
]]>
            </full-stacktrace>
          </exception> <!-- java.lang.AssertionError -->
          <reporter-output>
          </reporter-output>
        </test-method> <!-- TC_04 -->
        <test-method status="PASS" signature="TC_05()[pri:0, instance:autotest.Lession06@7e0babb1]" name="TC_05" duration-ms="213" started-at="2019-11-21T14:09:47Z" finished-at="2019-11-21T14:09:48Z">
          <reporter-output>
          </reporter-output>
        </test-method> <!-- TC_05 -->
        <test-method status="PASS" signature="afterClass()[pri:0, instance:autotest.Lession06@7e0babb1]" name="afterClass" is-config="true" duration-ms="137" started-at="2019-11-21T14:09:48Z" finished-at="2019-11-21T14:09:48Z">
          <reporter-output>
          </reporter-output>
        </test-method> <!-- afterClass -->
      </class> <!-- autotest.Lession06 -->
    </test> <!-- Default test -->
  </suite> <!-- Default suite -->
</testng-results>
